WARNING:torch.distributed.run:
*****************************************
Setting OMP_NUM_THREADS environment variable for each process to be 1 in default, to avoid your system being overloaded, please further tune the variable for optimal performance in your application as needed. 
*****************************************
Traceback (most recent call last):
  File "main.py", line 27, in <module>
    from datasets import load_dataset
ModuleNotFoundError: No module named 'datasets'
Traceback (most recent call last):
  File "main.py", line 27, in <module>
    from datasets import load_dataset
ModuleNotFoundError: No module named 'datasets'
Traceback (most recent call last):
  File "main.py", line 27, in <module>
    from datasets import load_dataset
ModuleNotFoundError: No module named 'datasets'
ERROR:torch.distributed.elastic.multiprocessing.api:failed (exitcode: 1) local_rank: 0 (pid: 79261) of binary: /data/anaconda/envs/torch16/bin/python
Traceback (most recent call last):
  File "/home/xf2022/.local/bin/torchrun", line 8, in <module>
    sys.exit(main())
  File "/home/xf2022/.local/lib/python3.6/site-packages/torch/distributed/elastic/multiprocessing/errors/__init__.py", line 345, in wrapper
    return f(*args, **kwargs)
  File "/home/xf2022/.local/lib/python3.6/site-packages/torch/distributed/run.py", line 719, in main
    run(args)
  File "/home/xf2022/.local/lib/python3.6/site-packages/torch/distributed/run.py", line 713, in run
    )(*cmd_args)
  File "/home/xf2022/.local/lib/python3.6/site-packages/torch/distributed/launcher/api.py", line 131, in __call__
    return launch_agent(self._config, self._entrypoint, list(args))
  File "/home/xf2022/.local/lib/python3.6/site-packages/torch/distributed/launcher/api.py", line 261, in launch_agent
    failures=result.failures,
torch.distributed.elastic.multiprocessing.errors.ChildFailedError: 
============================================================
main.py FAILED
------------------------------------------------------------
Failures:
[1]:
  time      : 2023-12-19_16:38:02
  host      : ta
  rank      : 1 (local_rank: 1)
  exitcode  : 1 (pid: 79262)
  error_file: <N/A>
  traceback : To enable traceback see: https://pytorch.org/docs/stable/elastic/errors.html
[2]:
  time      : 2023-12-19_16:38:02
  host      : ta
  rank      : 2 (local_rank: 2)
  exitcode  : 1 (pid: 79263)
  error_file: <N/A>
  traceback : To enable traceback see: https://pytorch.org/docs/stable/elastic/errors.html
------------------------------------------------------------
Root Cause (first observed failure):
[0]:
  time      : 2023-12-19_16:38:02
  host      : ta
  rank      : 0 (local_rank: 0)
  exitcode  : 1 (pid: 79261)
  error_file: <N/A>
  traceback : To enable traceback see: https://pytorch.org/docs/stable/elastic/errors.html
============================================================
